Workbook

Sheet README
A1: Emerging Growth Strategy — Bloomberg Data Template
A3: Generated: February 27, 2026
A5: FIRST-TIME SETUP
A6: 1. Open this file on a computer with Bloomberg Terminal and Excel Add-in active
A7: 2. Go to the Universe sheet — the BDS formula in A2 will pull ~2,000 Russell 2000 tickers
A8: 3. Press Ctrl+Shift+R to refresh all Bloomberg formulas (wait 5-10 minutes)
A9: 4. After Universe populates, filter column K for TRUE to find qualifying tickers
A10: 5. Copy qualifying tickers to the "Ticker Input" columns on Price History (col I) and Fundamentals (col M) sheets
A11: 6. Press Ctrl+Shift+R again to populate price and fundamental data
A12: 7. Factor Scores and Portfolio sheets auto-calculate from the data
A14: MONTHLY REFRESH
A15: 1. Open workbook on first trading day of month
... A25: See docs/06-bloomberg-data-pull.md for complete reference.

Sheet Universe
A1: Ticker | B1: Market Cap ($M) | C1: Exchange | D1: Avg Vol (20d) | E1: Price | F1: Dollar Volume | G1: MktCap Pass | H1: Exchange Pass | I1: DolVol Pass | J1: Price Pass | K1: ALL PASS
A2: =BDS("RTY Index","INDX_MEMBERS") | B2: =BDP(A2&" US Equity","CUR_MKT_CAP") | C2: =BDP(A2&" US Equity","EXCH_CODE") | D2: =BDP(A2&" US Equity","VOLUME_AVG_20D") | E2: =BDP(A2&" US Equity","PX_LAST") | F2: =D2*E2 | G2: =AND(B2>=50,B2<=10000) | H2: =OR(C2="NAS",C2="NYS",C2="ASE") | I2: =F2>=500000 | J2: =E2>=2 | K2: =AND(G2,H2,I2,J2)
B3: =BDP(A3&" US Equity","CUR_MKT_CAP") | C3: =BDP(A3&" US Equity","EXCH_CODE") | D3: =BDP(A3&" US Equity","VOLUME_AVG_20D") | E3: =BDP(A3&" US Equity","PX_LAST") | F3: =D3*E3 | G3: =AND(B3>=50,B3<=10000) | H3: =OR(C3="NAS",C3="NYS",C3="ASE") | I3: =F3>=500000 | J3: =E3>=2 | K3: =AND(G3,H3,I3,J3)
B4: =BDP(A4&" US Equity","CUR_MKT_CAP") | C4: =BDP(A4&" US Equity","EXCH_CODE") | D4: =BDP(A4&" US Equity","VOLUME_AVG_20D") | E4: =BDP(A4&" US Equity","PX_LAST") | F4: =D4*E4 | G4: =AND(B4>=50,B4<=10000) | H4: =OR(C4="NAS",C4="NYS",C4="ASE") | I4: =F4>=500000 | J4: =E4>=2 | K4: =AND(G4,H4,I4,J4)
B5: =BDP(A5&" US Equity","CUR_MKT_CAP") | C5: =BDP(A5&" US Equity","EXCH_CODE") | D5: =BDP(A5&" US Equity","VOLUME_AVG_20D") | E5: =BDP(A5&" US Equity","PX_LAST") | F5: =D5*E5 | G5: =AND(B5>=50,B5<=10000) | H5: =OR(C5="NAS",C5="NYS",C5="ASE") | I5: =F5>=500000 | J5: =E5>=2 | K5: =AND(G5,H5,I5,J5)
B6: =BDP(A6&" US Equity","CUR_MKT_CAP") | C6: =BDP(A6&" US Equity","EXCH_CODE") | D6: =BDP(A6&" US Equity","VOLUME_AVG_20D") | E6: =BDP(A6&" US Equity","PX_LAST") | F6: =D6*E6 | G6: =AND(B6>=50,B6<=10000) | H6: =OR(C6="NAS",C6="NYS",C6="ASE") | I6: =F6>=500000 | J6: =E6>=2 | K6: =AND(G6,H6,I6,J6)
B7: =BDP(A7&" US Equity","CUR_MKT_CAP") | C7: =BDP(A7&" US Equity","EXCH_CODE") | D7: =BDP(A7&" US Equity","VOLUME_AVG_20D") | E7: =BDP(A7&" US Equity","PX_LAST") | F7: =D7*E7 | G7: =AND(B7>=50,B7<=10000) | H7: =OR(C7="NAS",C7="NYS",C7="ASE") | I7: =F7>=500000 | J7: =E7>=2 | K7: =AND(G7,H7,I7,J7)
B8: =BDP(A8&" US Equity","CUR_MKT_CAP") | C8: =BDP(A8&" US Equity","EXCH_CODE") | D8: =BDP(A8&" US Equity","VOLUME_AVG_20D") | E8: =BDP(A8&" US Equity","PX_LAST") | F8: =D8*E8 | G8: =AND(B8>=50,B8<=10000) | H8: =OR(C8="NAS",C8="NYS",C8="ASE") | I8: =F8>=500000 | J8: =E8>=2 | K8: =AND(G8,H8,I8,J8)
B9: =BDP(A9&" US Equity","CUR_MKT_CAP") | C9: =BDP(A9&" US Equity","EXCH_CODE") | D9: =BDP(A9&" US Equity","VOLUME_AVG_20D") | E9: =BDP(A9&" US Equity","PX_LAST") | F9: =D9*E9 | G9: =AND(B9>=50,B9<=10000) | H9: =OR(C9="NAS",C9="NYS",C9="ASE") | I9: =F9>=500000 | J9: =E9>=2 | K9: =AND(G9,H9,I9,J9)
B10: =BDP(A10&" US Equity","CUR_MKT_CAP") | C10: =BDP(A10&" US Equity","EXCH_CODE") | D10: =BDP(A10&" US Equity","VOLUME_AVG_20D") | E10: =BDP(A10&" US Equity","PX_LAST") | F10: =D10*E10 | G10: =AND(B10>=50,B10<=10000) | H10: =OR(C10="NAS",C10="NYS",C10="ASE") | I10: =F10>=500000 | J10: =E10>=2 | K10: =AND(G10,H10,I10,J10)
B11: =BDP(A11&" US Equity","CUR_MKT_CAP") | C11: =BDP(A11&" US Equity","EXCH_CODE") | D11: =BDP(A11&" US Equity","VOLUME_AVG_20D") | E11: =BDP(A11&" US Equity","PX_LAST") | F11: =D11*E11 | G11: =AND(B11>=50,B11<=10000) | H11: =OR(C11="NAS",C11="NYS",C11="ASE") | I11: =F11>=500000 | J11: =E11>=2 | K11: =AND(G11,H11,I11,J11)
B12: =BDP(A12&" US Equity","CUR_MKT_CAP") | C12: =BDP(A12&" US Equity","EXCH_CODE") | D12: =BDP(A12&" US Equity","VOLUME_AVG_20D") | E12: =BDP(A12&" US Equity","PX_LAST") | F12: =D12*E12 | G12: =AND(B12>=50,B12<=10000) | H12: =OR(C12="NAS",C12="NYS",C12="ASE") | I12: =F12>=500000 | J12: =E12>=2 | K12: =AND(G12,H12,I12,J12)
B13: =BDP(A13&" US Equity","CUR_MKT_CAP") | C13: =BDP(A13&" US Equity","EXCH_CODE") | D13: =BDP(A13&" US Equity","VOLUME_AVG_20D") | E13: =BDP(A13&" US Equity","PX_LAST") | F13: =D13*E13 | G13: =AND(B13>=50,B13<=10000) | H13: =OR(C13="NAS",C13="NYS",C13="ASE") | I13: =F13>=500000 | J13: =E13>=2 | K13: =AND(G13,H13,I13,J13)
B14: =BDP(A14&" US Equity","CUR_MKT_CAP") | C14: =BDP(A14&" US Equity","EXCH_CODE") | D14: =BDP(A14&" US Equity","VOLUME_AVG_20D") | E14: =BDP(A14&" US Equity","PX_LAST") | F14: =D14*E14 | G14: =AND(B14>=50,B14<=10000) | H14: =OR(C14="NAS",C14="NYS",C14="ASE") | I14: =F14>=500000 | J14: =E14>=2 | K14: =AND(G14,H14,I14,J14)
... B2501: =BDP(A2501&" US Equity","CUR_MKT_CAP") | C2501: =BDP(A2501&" US Equity","EXCH_CODE") | D2501: =BDP(A2501&" US Equity","VOLUME_AVG_20D") | E2501: =BDP(A2501&" US Equity","PX_LAST") | F2501: =D2501*E2501 | G2501: =AND(B2501>=50,B2501<=10000) | H2501: =OR(C2501="NAS",C2501="NYS",C2501="ASE") | I2501: =F2501>=500000 | J2501: =E2501>=2 | K2501: =AND(G2501,H2501,I2501,J2501)

Sheet Price History
A1: INSTRUCTIONS: Paste qualifying tickers into column I (Ticker Input). BDH formulas auto-populate OHLCV data. Each ticker block = 320 rows.
A2: Ticker | B2: Date | C2: Open | D2: High | E2: Low | F2: Close | G2: Volume | I2: Ticker Input
A3: =I3 | B3: =BDH(A3&" US Equity","PX_OPEN,PX_HIGH,PX_LOW,PX_LAST,VOLUME",TEXT(EDATE(TODAY(),-15),"MM/DD/YYYY"),TEXT(TODAY(),"MM/DD/YYYY"),"Days","A","Fill","P","CshAdjNormal","Y","CshAdjAbnormal","Y")
A323: =I4 | B323: =BDH(A323&" US Equity","PX_OPEN,PX_HIGH,PX_LOW,PX_LAST,VOLUME",TEXT(EDATE(TODAY(),-15),"MM/DD/YYYY"),TEXT(TODAY(),"MM/DD/YYYY"),"Days","A","Fill","P","CshAdjNormal","Y","CshAdjAbnormal","Y")
A643: =I5 | B643: =BDH(A643&" US Equity","PX_OPEN,PX_HIGH,PX_LOW,PX_LAST,VOLUME",TEXT(EDATE(TODAY(),-15),"MM/DD/YYYY"),TEXT(TODAY(),"MM/DD/YYYY"),"Days","A","Fill","P","CshAdjNormal","Y","CshAdjAbnormal","Y")
A963: =I6 | B963: =BDH(A963&" US Equity","PX_OPEN,PX_HIGH,PX_LOW,PX_LAST,VOLUME",TEXT(EDATE(TODAY(),-15),"MM/DD/YYYY"),TEXT(TODAY(),"MM/DD/YYYY"),"Days","A","Fill","P","CshAdjNormal","Y","CshAdjAbnormal","Y")
A1283: =I7 | B1283: =BDH(A1283&" US Equity","PX_OPEN,PX_HIGH,PX_LOW,PX_LAST,VOLUME",TEXT(EDATE(TODAY(),-15),"MM/DD/YYYY"),TEXT(TODAY(),"MM/DD/YYYY"),"Days","A","Fill","P","CshAdjNormal","Y","CshAdjAbnormal","Y")
A1603: =I8 | B1603: =BDH(A1603&" US Equity","PX_OPEN,PX_HIGH,PX_LOW,PX_LAST,VOLUME",TEXT(EDATE(TODAY(),-15),"MM/DD/YYYY"),TEXT(TODAY(),"MM/DD/YYYY"),"Days","A","Fill","P","CshAdjNormal","Y","CshAdjAbnormal","Y")
A1923: =I9 | B1923: =BDH(A1923&" US Equity","PX_OPEN,PX_HIGH,PX_LOW,PX_LAST,VOLUME",TEXT(EDATE(TODAY(),-15),"MM/DD/YYYY"),TEXT(TODAY(),"MM/DD/YYYY"),"Days","A","Fill","P","CshAdjNormal","Y","CshAdjAbnormal","Y")
A2243: =I10 | B2243: =BDH(A2243&" US Equity","PX_OPEN,PX_HIGH,PX_LOW,PX_LAST,VOLUME",TEXT(EDATE(TODAY(),-15),"MM/DD/YYYY"),TEXT(TODAY(),"MM/DD/YYYY"),"Days","A","Fill","P","CshAdjNormal","Y","CshAdjAbnormal","Y")
A2563: =I11 | B2563: =BDH(A2563&" US Equity","PX_OPEN,PX_HIGH,PX_LOW,PX_LAST,VOLUME",TEXT(EDATE(TODAY(),-15),"MM/DD/YYYY"),TEXT(TODAY(),"MM/DD/YYYY"),"Days","A","Fill","P","CshAdjNormal","Y","CshAdjAbnormal","Y")
A2883: =I12 | B2883: =BDH(A2883&" US Equity","PX_OPEN,PX_HIGH,PX_LOW,PX_LAST,VOLUME",TEXT(EDATE(TODAY(),-15),"MM/DD/YYYY"),TEXT(TODAY(),"MM/DD/YYYY"),"Days","A","Fill","P","CshAdjNormal","Y","CshAdjAbnormal","Y")
A3203: =I13 | B3203: =BDH(A3203&" US Equity","PX_OPEN,PX_HIGH,PX_LOW,PX_LAST,VOLUME",TEXT(EDATE(TODAY(),-15),"MM/DD/YYYY"),TEXT(TODAY(),"MM/DD/YYYY"),"Days","A","Fill","P","CshAdjNormal","Y","CshAdjAbnormal","Y")
A3523: =I14 | B3523: =BDH(A3523&" US Equity","PX_OPEN,PX_HIGH,PX_LOW,PX_LAST,VOLUME",TEXT(EDATE(TODAY(),-15),"MM/DD/YYYY"),TEXT(TODAY(),"MM/DD/YYYY"),"Days","A","Fill","P","CshAdjNormal","Y","CshAdjAbnormal","Y")
A3843: =I15 | B3843: =BDH(A3843&" US Equity","PX_OPEN,PX_HIGH,PX_LOW,PX_LAST,VOLUME",TEXT(EDATE(TODAY(),-15),"MM/DD/YYYY"),TEXT(TODAY(),"MM/DD/YYYY"),"Days","A","Fill","P","CshAdjNormal","Y","CshAdjAbnormal","Y")
A4163: =I16 | B4163: =BDH(A4163&" US Equity","PX_OPEN,PX_HIGH,PX_LOW,PX_LAST,VOLUME",TEXT(EDATE(TODAY(),-15),"MM/DD/YYYY"),TEXT(TODAY(),"MM/DD/YYYY"),"Days","A","Fill","P","CshAdjNormal","Y","CshAdjAbnormal","Y")
A4483: =I17 | B4483: =BDH(A4483&" US Equity","PX_OPEN,PX_HIGH,PX_LOW,PX_LAST,VOLUME",TEXT(EDATE(TODAY(),-15),"MM/DD/YYYY"),TEXT(TODAY(),"MM/DD/YYYY"),"Days","A","Fill","P","CshAdjNormal","Y","CshAdjAbnormal","Y")
A4803: =I18 | B4803: =BDH(A4803&" US Equity","PX_OPEN,PX_HIGH,PX_LOW,PX_LAST,VOLUME",TEXT(EDATE(TODAY(),-15),"MM/DD/YYYY"),TEXT(TODAY(),"MM/DD/YYYY"),"Days","A","Fill","P","CshAdjNormal","Y","CshAdjAbnormal","Y")
A5123: =I19 | B5123: =BDH(A5123&" US Equity","PX_OPEN,PX_HIGH,PX_LOW,PX_LAST,VOLUME",TEXT(EDATE(TODAY(),-15),"MM/DD/YYYY"),TEXT(TODAY(),"MM/DD/YYYY"),"Days","A","Fill","P","CshAdjNormal","Y","CshAdjAbnormal","Y")
A5443: =I20 | B5443: =BDH(A5443&" US Equity","PX_OPEN,PX_HIGH,PX_LOW,PX_LAST,VOLUME",TEXT(EDATE(TODAY(),-15),"MM/DD/YYYY"),TEXT(TODAY(),"MM/DD/YYYY"),"Days","A","Fill","P","CshAdjNormal","Y","CshAdjAbnormal","Y")
A5763: =I21 | B5763: =BDH(A5763&" US Equity","PX_OPEN,PX_HIGH,PX_LOW,PX_LAST,VOLUME",TEXT(EDATE(TODAY(),-15),"MM/DD/YYYY"),TEXT(TODAY(),"MM/DD/YYYY"),"Days","A","Fill","P","CshAdjNormal","Y","CshAdjAbnormal","Y")
A6083: =I22 | B6083: =BDH(A6083&" US Equity","PX_OPEN,PX_HIGH,PX_LOW,PX_LAST,VOLUME",TEXT(EDATE(TODAY(),-15),"MM/DD/YYYY"),TEXT(TODAY(),"MM/DD/YYYY"),"Days","A","Fill","P","CshAdjNormal","Y","CshAdjAbnormal","Y")
A6403: =I23 | B6403: =BDH(A6403&" US Equity","PX_OPEN,PX_HIGH,PX_LOW,PX_LAST,VOLUME",TEXT(EDATE(TODAY(),-15),"MM/DD/YYYY"),TEXT(TODAY(),"MM/DD/YYYY"),"Days","A","Fill","P","CshAdjNormal","Y","CshAdjAbnormal","Y")
A6723: =I24 | B6723: =BDH(A6723&" US Equity","PX_OPEN,PX_HIGH,PX_LOW,PX_LAST,VOLUME",TEXT(EDATE(TODAY(),-15),"MM/DD/YYYY"),TEXT(TODAY(),"MM/DD/YYYY"),"Days","A","Fill","P","CshAdjNormal","Y","CshAdjAbnormal","Y")
A7043: =I25 | B7043: =BDH(A7043&" US Equity","PX_OPEN,PX_HIGH,PX_LOW,PX_LAST,VOLUME",TEXT(EDATE(TODAY(),-15),"MM/DD/YYYY"),TEXT(TODAY(),"MM/DD/YYYY"),"Days","A","Fill","P","CshAdjNormal","Y","CshAdjAbnormal","Y")
A7363: =I26 | B7363: =BDH(A7363&" US Equity","PX_OPEN,PX_HIGH,PX_LOW,PX_LAST,VOLUME",TEXT(EDATE(TODAY(),-15),"MM/DD/YYYY"),TEXT(TODAY(),"MM/DD/YYYY"),"Days","A","Fill","P","CshAdjNormal","Y","CshAdjAbnormal","Y")
A7683: =I27 | B7683: =BDH(A7683&" US Equity","PX_OPEN,PX_HIGH,PX_LOW,PX_LAST,VOLUME",TEXT(EDATE(TODAY(),-15),"MM/DD/YYYY"),TEXT(TODAY(),"MM/DD/YYYY"),"Days","A","Fill","P","CshAdjNormal","Y","CshAdjAbnormal","Y")
A8003: =I28 | B8003: =BDH(A8003&" US Equity","PX_OPEN,PX_HIGH,PX_LOW,PX_LAST,VOLUME",TEXT(EDATE(TODAY(),-15),"MM/DD/YYYY"),TEXT(TODAY(),"MM/DD/YYYY"),"Days","A","Fill","P","CshAdjNormal","Y","CshAdjAbnormal","Y")
A8323: =I29 | B8323: =BDH(A8323&" US Equity","PX_OPEN,PX_HIGH,PX_LOW,PX_LAST,VOLUME",TEXT(EDATE(TODAY(),-15),"MM/DD/YYYY"),TEXT(TODAY(),"MM/DD/YYYY"),"Days","A","Fill","P","CshAdjNormal","Y","CshAdjAbnormal","Y")
A8643: =I30 | B8643: =BDH(A8643&" US Equity","PX_OPEN,PX_HIGH,PX_LOW,PX_LAST,VOLUME",TEXT(EDATE(TODAY(),-15),"MM/DD/YYYY"),TEXT(TODAY(),"MM/DD/YYYY"),"Days","A","Fill","P","CshAdjNormal","Y","CshAdjAbnormal","Y")
A8963: =I31 | B8963: =BDH(A8963&" US Equity","PX_OPEN,PX_HIGH,PX_LOW,PX_LAST,VOLUME",TEXT(EDATE(TODAY(),-15),"MM/DD/YYYY"),TEXT(TODAY(),"MM/DD/YYYY"),"Days","A","Fill","P","CshAdjNormal","Y","CshAdjAbnormal","Y")
A9283: =I32 | B9283: =BDH(A9283&" US Equity","PX_OPEN,PX_HIGH,PX_LOW,PX_LAST,VOLUME",TEXT(EDATE(TODAY(),-15),"MM/DD/YYYY"),TEXT(TODAY(),"MM/DD/YYYY"),"Days","A","Fill","P","CshAdjNormal","Y","CshAdjAbnormal","Y")
A9603: =I33 | B9603: =BDH(A9603&" US Equity","PX_OPEN,PX_HIGH,PX_LOW,PX_LAST,VOLUME",TEXT(EDATE(TODAY(),-15),"MM/DD/YYYY"),TEXT(TODAY(),"MM/DD/YYYY"),"Days","A","Fill","P","CshAdjNormal","Y","CshAdjAbnormal","Y")
A9923: =I34 | B9923: =BDH(A9923&" US Equity","PX_OPEN,PX_HIGH,PX_LOW,PX_LAST,VOLUME",TEXT(EDATE(TODAY(),-15),"MM/DD/YYYY"),TEXT(TODAY(),"MM/DD/YYYY"),"Days","A","Fill","P","CshAdjNormal","Y","CshAdjAbnormal","Y")
A10243: =I35 | B10243: =BDH(A10243&" US Equity","PX_OPEN,PX_HIGH,PX_LOW,PX_LAST,VOLUME",TEXT(EDATE(TODAY(),-15),"MM/DD/YYYY"),TEXT(TODAY(),"MM/DD/YYYY"),"Days","A","Fill","P","CshAdjNormal","Y","CshAdjAbnormal","Y")
A10563: =I36 | B10563: =BDH(A10563&" US Equity","PX_OPEN,PX_HIGH,PX_LOW,PX_LAST,VOLUME",TEXT(EDATE(TODAY(),-15),"MM/DD/YYYY"),TEXT(TODAY(),"MM/DD/YYYY"),"Days","A","Fill","P","CshAdjNormal","Y","CshAdjAbnormal","Y")
A10883: =I37 | B10883: =BDH(A10883&" US Equity","PX_OPEN,PX_HIGH,PX_LOW,PX_LAST,VOLUME",TEXT(EDATE(TODAY(),-15),"MM/DD/YYYY"),TEXT(TODAY(),"MM/DD/YYYY"),"Days","A","Fill","P","CshAdjNormal","Y","CshAdjAbnormal","Y")
A11203: =I38 | B11203: =BDH(A11203&" US Equity","PX_OPEN,PX_HIGH,PX_LOW,PX_LAST,VOLUME",TEXT(EDATE(TODAY(),-15),"MM/DD/YYYY"),TEXT(TODAY(),"MM/DD/YYYY"),"Days","A","Fill","P","CshAdjNormal","Y","CshAdjAbnormal","Y")
A11523: =I39 | B11523: =BDH(A11523&" US Equity","PX_OPEN,PX_HIGH,PX_LOW,PX_LAST,VOLUME",TEXT(EDATE(TODAY(),-15),"MM/DD/YYYY"),TEXT(TODAY(),"MM/DD/YYYY"),"Days","A","Fill","P","CshAdjNormal","Y","CshAdjAbnormal","Y")
A11843: =I40 | B11843: =BDH(A11843&" US Equity","PX_OPEN,PX_HIGH,PX_LOW,PX_LAST,VOLUME",TEXT(EDATE(TODAY(),-15),"MM/DD/YYYY"),TEXT(TODAY(),"MM/DD/YYYY"),"Days","A","Fill","P","CshAdjNormal","Y","CshAdjAbnormal","Y")
...

Sheet Fundamentals
A1: Ticker | B1: EPS Date | C1: EPS | J1: Rev Date | K1: Revenue | L1: EPS YoY % | M1: Ticker Input | N1: Rev YoY %
A2: =M2 | B2: =BDH(A2&" US Equity","IS_DILUTED_EPS",TEXT(EDATE(TODAY(),-24),"MM/DD/YYYY"),TEXT(TODAY(),"MM/DD/YYYY"),"Per","Q","Days","A","Fill","P") | J2: =BDH(A2&" US Equity","SALES_REV_TURN",TEXT(EDATE(TODAY(),-24),"MM/DD/YYYY"),TEXT(TODAY(),"MM/DD/YYYY"),"Per","Q","Days","A","Fill","P") | L2: =IF(C5=0,IF(C9>0,999,0),IF(C5<0,IF(C9>0,999,0),(C9-C5)/ABS(C5)*100)) | N2: =IF(K5<=0,IF(K9>0,999,0),(K9-K5)/K5*100)
A12: =M3 | B12: =BDH(A12&" US Equity","IS_DILUTED_EPS",TEXT(EDATE(TODAY(),-24),"MM/DD/YYYY"),TEXT(TODAY(),"MM/DD/YYYY"),"Per","Q","Days","A","Fill","P") | J12: =BDH(A12&" US Equity","SALES_REV_TURN",TEXT(EDATE(TODAY(),-24),"MM/DD/YYYY"),TEXT(TODAY(),"MM/DD/YYYY"),"Per","Q","Days","A","Fill","P") | L12: =IF(C15=0,IF(C19>0,999,0),IF(C15<0,IF(C19>0,999,0),(C19-C15)/ABS(C15)*100)) | N12: =IF(K15<=0,IF(K19>0,999,0),(K19-K15)/K15*100)
A22: =M4 | B22: =BDH(A22&" US Equity","IS_DILUTED_EPS",TEXT(EDATE(TODAY(),-24),"MM/DD/YYYY"),TEXT(TODAY(),"MM/DD/YYYY"),"Per","Q","Days","A","Fill","P") | J22: =BDH(A22&" US Equity","SALES_REV_TURN",TEXT(EDATE(TODAY(),-24),"MM/DD/YYYY"),TEXT(TODAY(),"MM/DD/YYYY"),"Per","Q","Days","A","Fill","P") | L22: =IF(C25=0,IF(C29>0,999,0),IF(C25<0,IF(C29>0,999,0),(C29-C25)/ABS(C25)*100)) | N22: =IF(K25<=0,IF(K29>0,999,0),(K29-K25)/K25*100)
A32: =M5 | B32: =BDH(A32&" US Equity","IS_DILUTED_EPS",TEXT(EDATE(TODAY(),-24),"MM/DD/YYYY"),TEXT(TODAY(),"MM/DD/YYYY"),"Per","Q","Days","A","Fill","P") | J32: =BDH(A32&" US Equity","SALES_REV_TURN",TEXT(EDATE(TODAY(),-24),"MM/DD/YYYY"),TEXT(TODAY(),"MM/DD/YYYY"),"Per","Q","Days","A","Fill","P") | L32: =IF(C35=0,IF(C39>0,999,0),IF(C35<0,IF(C39>0,999,0),(C39-C35)/ABS(C35)*100)) | N32: =IF(K35<=0,IF(K39>0,999,0),(K39-K35)/K35*100)
A42: =M6 | B42: =BDH(A42&" US Equity","IS_DILUTED_EPS",TEXT(EDATE(TODAY(),-24),"MM/DD/YYYY"),TEXT(TODAY(),"MM/DD/YYYY"),"Per","Q","Days","A","Fill","P") | J42: =BDH(A42&" US Equity","SALES_REV_TURN",TEXT(EDATE(TODAY(),-24),"MM/DD/YYYY"),TEXT(TODAY(),"MM/DD/YYYY"),"Per","Q","Days","A","Fill","P") | L42: =IF(C45=0,IF(C49>0,999,0),IF(C45<0,IF(C49>0,999,0),(C49-C45)/ABS(C45)*100)) | N42: =IF(K45<=0,IF(K49>0,999,0),(K49-K45)/K45*100)
A52: =M7 | B52: =BDH(A52&" US Equity","IS_DILUTED_EPS",TEXT(EDATE(TODAY(),-24),"MM/DD/YYYY"),TEXT(TODAY(),"MM/DD/YYYY"),"Per","Q","Days","A","Fill","P") | J52: =BDH(A52&" US Equity","SALES_REV_TURN",TEXT(EDATE(TODAY(),-24),"MM/DD/YYYY"),TEXT(TODAY(),"MM/DD/YYYY"),"Per","Q","Days","A","Fill","P") | L52: =IF(C55=0,IF(C59>0,999,0),IF(C55<0,IF(C59>0,999,0),(C59-C55)/ABS(C55)*100)) | N52: =IF(K55<=0,IF(K59>0,999,0),(K59-K55)/K55*100)
A62: =M8 | B62: =BDH(A62&" US Equity","IS_DILUTED_EPS",TEXT(EDATE(TODAY(),-24),"MM/DD/YYYY"),TEXT(TODAY(),"MM/DD/YYYY"),"Per","Q","Days","A","Fill","P") | J62: =BDH(A62&" US Equity","SALES_REV_TURN",TEXT(EDATE(TODAY(),-24),"MM/DD/YYYY"),TEXT(TODAY(),"MM/DD/YYYY"),"Per","Q","Days","A","Fill","P") | L62: =IF(C65=0,IF(C69>0,999,0),IF(C65<0,IF(C69>0,999,0),(C69-C65)/ABS(C65)*100)) | N62: =IF(K65<=0,IF(K69>0,999,0),(K69-K65)/K65*100)
A72: =M9 | B72: =BDH(A72&" US Equity","IS_DILUTED_EPS",TEXT(EDATE(TODAY(),-24),"MM/DD/YYYY"),TEXT(TODAY(),"MM/DD/YYYY"),"Per","Q","Days","A","Fill","P") | J72: =BDH(A72&" US Equity","SALES_REV_TURN",TEXT(EDATE(TODAY(),-24),"MM/DD/YYYY"),TEXT(TODAY(),"MM/DD/YYYY"),"Per","Q","Days","A","Fill","P") | L72: =IF(C75=0,IF(C79>0,999,0),IF(C75<0,IF(C79>0,999,0),(C79-C75)/ABS(C75)*100)) | N72: =IF(K75<=0,IF(K79>0,999,0),(K79-K75)/K75*100)
A82: =M10 | B82: =BDH(A82&" US Equity","IS_DILUTED_EPS",TEXT(EDATE(TODAY(),-24),"MM/DD/YYYY"),TEXT(TODAY(),"MM/DD/YYYY"),"Per","Q","Days","A","Fill","P") | J82: =BDH(A82&" US Equity","SALES_REV_TURN",TEXT(EDATE(TODAY(),-24),"MM/DD/YYYY"),TEXT(TODAY(),"MM/DD/YYYY"),"Per","Q","Days","A","Fill","P") | L82: =IF(C85=0,IF(C89>0,999,0),IF(C85<0,IF(C89>0,999,0),(C89-C85)/ABS(C85)*100)) | N82: =IF(K85<=0,IF(K89>0,999,0),(K89-K85)/K85*100)
A92: =M11 | B92: =BDH(A92&" US Equity","IS_DILUTED_EPS",TEXT(EDATE(TODAY(),-24),"MM/DD/YYYY"),TEXT(TODAY(),"MM/DD/YYYY"),"Per","Q","Days","A","Fill","P") | J92: =BDH(A92&" US Equity","SALES_REV_TURN",TEXT(EDATE(TODAY(),-24),"MM/DD/YYYY"),TEXT(TODAY(),"MM/DD/YYYY"),"Per","Q","Days","A","Fill","P") | L92: =IF(C95=0,IF(C99>0,999,0),IF(C95<0,IF(C99>0,999,0),(C99-C95)/ABS(C95)*100)) | N92: =IF(K95<=0,IF(K99>0,999,0),(K99-K95)/K95*100)
A102: =M12 | B102: =BDH(A102&" US Equity","IS_DILUTED_EPS",TEXT(EDATE(TODAY(),-24),"MM/DD/YYYY"),TEXT(TODAY(),"MM/DD/YYYY"),"Per","Q","Days","A","Fill","P") | J102: =BDH(A102&" US Equity","SALES_REV_TURN",TEXT(EDATE(TODAY(),-24),"MM/DD/YYYY"),TEXT(TODAY(),"MM/DD/YYYY"),"Per","Q","Days","A","Fill","P") | L102: =IF(C105=0,IF(C109>0,999,0),IF(C105<0,IF(C109>0,999,0),(C109-C105)/ABS(C105)*100)) | N102: =IF(K105<=0,IF(K109>0,999,0),(K109-K105)/K105*100)
A112: =M13 | B112: =BDH(A112&" US Equity","IS_DILUTED_EPS",TEXT(EDATE(TODAY(),-24),"MM/DD/YYYY"),TEXT(TODAY(),"MM/DD/YYYY"),"Per","Q","Days","A","Fill","P") | J112: =BDH(A112&" US Equity","SALES_REV_TURN",TEXT(EDATE(TODAY(),-24),"MM/DD/YYYY"),TEXT(TODAY(),"MM/DD/YYYY"),"Per","Q","Days","A","Fill","P") | L112: =IF(C115=0,IF(C119>0,999,0),IF(C115<0,IF(C119>0,999,0),(C119-C115)/ABS(C115)*100)) | N112: =IF(K115<=0,IF(K119>0,999,0),(K119-K115)/K115*100)
A122: =M14 | B122: =BDH(A122&" US Equity","IS_DILUTED_EPS",TEXT(EDATE(TODAY(),-24),"MM/DD/YYYY"),TEXT(TODAY(),"MM/DD/YYYY"),"Per","Q","Days","A","Fill","P") | J122: =BDH(A122&" US Equity","SALES_REV_TURN",TEXT(EDATE(TODAY(),-24),"MM/DD/YYYY"),TEXT(TODAY(),"MM/DD/YYYY"),"Per","Q","Days","A","Fill","P") | L122: =IF(C125=0,IF(C129>0,999,0),IF(C125<0,IF(C129>0,999,0),(C129-C125)/ABS(C125)*100)) | N122: =IF(K125<=0,IF(K129>0,999,0),(K129-K125)/K125*100)
A132: =M15 | B132: =BDH(A132&" US Equity","IS_DILUTED_EPS",TEXT(EDATE(TODAY(),-24),"MM/DD/YYYY"),TEXT(TODAY(),"MM/DD/YYYY"),"Per","Q","Days","A","Fill","P") | J132: =BDH(A132&" US Equity","SALES_REV_TURN",TEXT(EDATE(TODAY(),-24),"MM/DD/YYYY"),TEXT(TODAY(),"MM/DD/YYYY"),"Per","Q","Days","A","Fill","P") | L132: =IF(C135=0,IF(C139>0,999,0),IF(C135<0,IF(C139>0,999,0),(C139-C135)/ABS(C135)*100)) | N132: =IF(K135<=0,IF(K139>0,999,0),(K139-K135)/K135*100)
A142: =M16 | B142: =BDH(A142&" US Equity","IS_DILUTED_EPS",TEXT(EDATE(TODAY(),-24),"MM/DD/YYYY"),TEXT(TODAY(),"MM/DD/YYYY"),"Per","Q","Days","A","Fill","P") | J142: =BDH(A142&" US Equity","SALES_REV_TURN",TEXT(EDATE(TODAY(),-24),"MM/DD/YYYY"),TEXT(TODAY(),"MM/DD/YYYY"),"Per","Q","Days","A","Fill","P") | L142: =IF(C145=0,IF(C149>0,999,0),IF(C145<0,IF(C149>0,999,0),(C149-C145)/ABS(C145)*100)) | N142: =IF(K145<=0,IF(K149>0,999,0),(K149-K145)/K145*100)
A152: =M17 | B152: =BDH(A152&" US Equity","IS_DILUTED_EPS",TEXT(EDATE(TODAY(),-24),"MM/DD/YYYY"),TEXT(TODAY(),"MM/DD/YYYY"),"Per","Q","Days","A","Fill","P") | J152: =BDH(A152&" US Equity","SALES_REV_TURN",TEXT(EDATE(TODAY(),-24),"MM/DD/YYYY"),TEXT(TODAY(),"MM/DD/YYYY"),"Per","Q","Days","A","Fill","P") | L152: =IF(C155=0,IF(C159>0,999,0),IF(C155<0,IF(C159>0,999,0),(C159-C155)/ABS(C155)*100)) | N152: =IF(K155<=0,IF(K159>0,999,0),(K159-K155)/K155*100)
A162: =M18 | B162: =BDH(A162&" US Equity","IS_DILUTED_EPS",TEXT(EDATE(TODAY(),-24),"MM/DD/YYYY"),TEXT(TODAY(),"MM/DD/YYYY"),"Per","Q","Days","A","Fill","P") | J162: =BDH(A162&" US Equity","SALES_REV_TURN",TEXT(EDATE(TODAY(),-24),"MM/DD/YYYY"),TEXT(TODAY(),"MM/DD/YYYY"),"Per","Q","Days","A","Fill","P") | L162: =IF(C165=0,IF(C169>0,999,0),IF(C165<0,IF(C169>0,999,0),(C169-C165)/ABS(C165)*100)) | N162: =IF(K165<=0,IF(K169>0,999,0),(K169-K165)/K165*100)
A172: =M19 | B172: =BDH(A172&" US Equity","IS_DILUTED_EPS",TEXT(EDATE(TODAY(),-24),"MM/DD/YYYY"),TEXT(TODAY(),"MM/DD/YYYY"),"Per","Q","Days","A","Fill","P") | J172: =BDH(A172&" US Equity","SALES_REV_TURN",TEXT(EDATE(TODAY(),-24),"MM/DD/YYYY"),TEXT(TODAY(),"MM/DD/YYYY"),"Per","Q","Days","A","Fill","P") | L172: =IF(C175=0,IF(C179>0,999,0),IF(C175<0,IF(C179>0,999,0),(C179-C175)/ABS(C175)*100)) | N172: =IF(K175<=0,IF(K179>0,999,0),(K179-K175)/K175*100)
A182: =M20 | B182: =BDH(A182&" US Equity","IS_DILUTED_EPS",TEXT(EDATE(TODAY(),-24),"MM/DD/YYYY"),TEXT(TODAY(),"MM/DD/YYYY"),"Per","Q","Days","A","Fill","P") | J182: =BDH(A182&" US Equity","SALES_REV_TURN",TEXT(EDATE(TODAY(),-24),"MM/DD/YYYY"),TEXT(TODAY(),"MM/DD/YYYY"),"Per","Q","Days","A","Fill","P") | L182: =IF(C185=0,IF(C189>0,999,0),IF(C185<0,IF(C189>0,999,0),(C189-C185)/ABS(C185)*100)) | N182: =IF(K185<=0,IF(K189>0,999,0),(K189-K185)/K185*100)
A192: =M21 | B192: =BDH(A192&" US Equity","IS_DILUTED_EPS",TEXT(EDATE(TODAY(),-24),"MM/DD/YYYY"),TEXT(TODAY(),"MM/DD/YYYY"),"Per","Q","Days","A","Fill","P") | J192: =BDH(A192&" US Equity","SALES_REV_TURN",TEXT(EDATE(TODAY(),-24),"MM/DD/YYYY"),TEXT(TODAY(),"MM/DD/YYYY"),"Per","Q","Days","A","Fill","P") | L192: =IF(C195=0,IF(C199>0,999,0),IF(C195<0,IF(C199>0,999,0),(C199-C195)/ABS(C195)*100)) | N192: =IF(K195<=0,IF(K199>0,999,0),(K199-K195)/K195*100)
A202: =M22 | B202: =BDH(A202&" US Equity","IS_DILUTED_EPS",TEXT(EDATE(TODAY(),-24),"MM/DD/YYYY"),TEXT(TODAY(),"MM/DD/YYYY"),"Per","Q","Days","A","Fill","P") | J202: =BDH(A202&" US Equity","SALES_REV_TURN",TEXT(EDATE(TODAY(),-24),"MM/DD/YYYY"),TEXT(TODAY(),"MM/DD/YYYY"),"Per","Q","Days","A","Fill","P") | L202: =IF(C205=0,IF(C209>0,999,0),IF(C205<0,IF(C209>0,999,0),(C209-C205)/ABS(C205)*100)) | N202: =IF(K205<=0,IF(K209>0,999,0),(K209-K205)/K205*100)
A212: =M23 | B212: =BDH(A212&" US Equity","IS_DILUTED_EPS",TEXT(EDATE(TODAY(),-24),"MM/DD/YYYY"),TEXT(TODAY(),"MM/DD/YYYY"),"Per","Q","Days","A","Fill","P") | J212: =BDH(A212&" US Equity","SALES_REV_TURN",TEXT(EDATE(TODAY(),-24),"MM/DD/YYYY"),TEXT(TODAY(),"MM/DD/YYYY"),"Per","Q","Days","A","Fill","P") | L212: =IF(C215=0,IF(C219>0,999,0),IF(C215<0,IF(C219>0,999,0),(C219-C215)/ABS(C215)*100)) | N212: =IF(K215<=0,IF(K219>0,999,0),(K219-K215)/K215*100)
A222: =M24 | B222: =BDH(A222&" US Equity","IS_DILUTED_EPS",TEXT(EDATE(TODAY(),-24),"MM/DD/YYYY"),TEXT(TODAY(),"MM/DD/YYYY"),"Per","Q","Days","A","Fill","P") | J222: =BDH(A222&" US Equity","SALES_REV_TURN",TEXT(EDATE(TODAY(),-24),"MM/DD/YYYY"),TEXT(TODAY(),"MM/DD/YYYY"),"Per","Q","Days","A","Fill","P") | L222: =IF(C225=0,IF(C229>0,999,0),IF(C225<0,IF(C229>0,999,0),(C229-C225)/ABS(C225)*100)) | N222: =IF(K225<=0,IF(K229>0,999,0),(K229-K225)/K225*100)
A232: =M25 | B232: =BDH(A232&" US Equity","IS_DILUTED_EPS",TEXT(EDATE(TODAY(),-24),"MM/DD/YYYY"),TEXT(TODAY(),"MM/DD/YYYY"),"Per","Q","Days","A","Fill","P") | J232: =BDH(A232&" US Equity","SALES_REV_TURN",TEXT(EDATE(TODAY(),-24),"MM/DD/YYYY"),TEXT(TODAY(),"MM/DD/YYYY"),"Per","Q","Days","A","Fill","P") | L232: =IF(C235=0,IF(C239>0,999,0),IF(C235<0,IF(C239>0,999,0),(C239-C235)/ABS(C235)*100)) | N232: =IF(K235<=0,IF(K239>0,999,0),(K239-K235)/K235*100)
A242: =M26 | B242: =BDH(A242&" US Equity","IS_DILUTED_EPS",TEXT(EDATE(TODAY(),-24),"MM/DD/YYYY"),TEXT(TODAY(),"MM/DD/YYYY"),"Per","Q","Days","A","Fill","P") | J242: =BDH(A242&" US Equity","SALES_REV_TURN",TEXT(EDATE(TODAY(),-24),"MM/DD/YYYY"),TEXT(TODAY(),"MM/DD/YYYY"),"Per","Q","Days","A","Fill","P") | L242: =IF(C245=0,IF(C249>0,999,0),IF(C245<0,IF(C249>0,999,0),(C249-C245)/ABS(C245)*100)) | N242: =IF(K245<=0,IF(K249>0,999,0),(K249-K245)/K245*100)
A252: =M27 | B252: =BDH(A252&" US Equity","IS_DILUTED_EPS",TEXT(EDATE(TODAY(),-24),"MM/DD/YYYY"),TEXT(TODAY(),"MM/DD/YYYY"),"Per","Q","Days","A","Fill","P") | J252: =BDH(A252&" US Equity","SALES_REV_TURN",TEXT(EDATE(TODAY(),-24),"MM/DD/YYYY"),TEXT(TODAY(),"MM/DD/YYYY"),"Per","Q","Days","A","Fill","P") | L252: =IF(C255=0,IF(C259>0,999,0),IF(C255<0,IF(C259>0,999,0),(C259-C255)/ABS(C255)*100)) | N252: =IF(K255<=0,IF(K259>0,999,0),(K259-K255)/K255*100)
A262: =M28 | B262: =BDH(A262&" US Equity","IS_DILUTED_EPS",TEXT(EDATE(TODAY(),-24),"MM/DD/YYYY"),TEXT(TODAY(),"MM/DD/YYYY"),"Per","Q","Days","A","Fill","P") | J262: =BDH(A262&" US Equity","SALES_REV_TURN",TEXT(EDATE(TODAY(),-24),"MM/DD/YYYY"),TEXT(TODAY(),"MM/DD/YYYY"),"Per","Q","Days","A","Fill","P") | L262: =IF(C265=0,IF(C269>0,999,0),IF(C265<0,IF(C269>0,999,0),(C269-C265)/ABS(C265)*100)) | N262: =IF(K265<=0,IF(K269>0,999,0),(K269-K265)/K265*100)
A272: =M29 | B272: =BDH(A272&" US Equity","IS_DILUTED_EPS",TEXT(EDATE(TODAY(),-24),"MM/DD/YYYY"),TEXT(TODAY(),"MM/DD/YYYY"),"Per","Q","Days","A","Fill","P") | J272: =BDH(A272&" US Equity","SALES_REV_TURN",TEXT(EDATE(TODAY(),-24),"MM/DD/YYYY"),TEXT(TODAY(),"MM/DD/YYYY"),"Per","Q","Days","A","Fill","P") | L272: =IF(C275=0,IF(C279>0,999,0),IF(C275<0,IF(C279>0,999,0),(C279-C275)/ABS(C275)*100)) | N272: =IF(K275<=0,IF(K279>0,999,0),(K279-K275)/K275*100)
A282: =M30 | B282: =BDH(A282&" US Equity","IS_DILUTED_EPS",TEXT(EDATE(TODAY(),-24),"MM/DD/YYYY"),TEXT(TODAY(),"MM/DD/YYYY"),"Per","Q","Days","A","Fill","P") | J282: =BDH(A282&" US Equity","SALES_REV_TURN",TEXT(EDATE(TODAY(),-24),"MM/DD/YYYY"),TEXT(TODAY(),"MM/DD/YYYY"),"Per","Q","Days","A","Fill","P") | L282: =IF(C285=0,IF(C289>0,999,0),IF(C285<0,IF(C289>0,999,0),(C289-C285)/ABS(C285)*100)) | N282: =IF(K285<=0,IF(K289>0,999,0),(K289-K285)/K285*100)
A292: =M31 | B292: =BDH(A292&" US Equity","IS_DILUTED_EPS",TEXT(EDATE(TODAY(),-24),"MM/DD/YYYY"),TEXT(TODAY(),"MM/DD/YYYY"),"Per","Q","Days","A","Fill","P") | J292: =BDH(A292&" US Equity","SALES_REV_TURN",TEXT(EDATE(TODAY(),-24),"MM/DD/YYYY"),TEXT(TODAY(),"MM/DD/YYYY"),"Per","Q","Days","A","Fill","P") | L292: =IF(C295=0,IF(C299>0,999,0),IF(C295<0,IF(C299>0,999,0),(C299-C295)/ABS(C295)*100)) | N292: =IF(K295<=0,IF(K299>0,999,0),(K299-K295)/K295*100)
A302: =M32 | B302: =BDH(A302&" US Equity","IS_DILUTED_EPS",TEXT(EDATE(TODAY(),-24),"MM/DD/YYYY"),TEXT(TODAY(),"MM/DD/YYYY"),"Per","Q","Days","A","Fill","P") | J302: =BDH(A302&" US Equity","SALES_REV_TURN",TEXT(EDATE(TODAY(),-24),"MM/DD/YYYY"),TEXT(TODAY(),"MM/DD/YYYY"),"Per","Q","Days","A","Fill","P") | L302: =IF(C305=0,IF(C309>0,999,0),IF(C305<0,IF(C309>0,999,0),(C309-C305)/ABS(C305)*100)) | N302: =IF(K305<=0,IF(K309>0,999,0),(K309-K305)/K305*100)
A312: =M33 | B312: =BDH(A312&" US Equity","IS_DILUTED_EPS",TEXT(EDATE(TODAY(),-24),"MM/DD/YYYY"),TEXT(TODAY(),"MM/DD/YYYY"),"Per","Q","Days","A","Fill","P") | J312: =BDH(A312&" US Equity","SALES_REV_TURN",TEXT(EDATE(TODAY(),-24),"MM/DD/YYYY"),TEXT(TODAY(),"MM/DD/YYYY"),"Per","Q","Days","A","Fill","P") | L312: =IF(C315=0,IF(C319>0,999,0),IF(C315<0,IF(C319>0,999,0),(C319-C315)/ABS(C315)*100)) | N312: =IF(K315<=0,IF(K319>0,999,0),(K319-K315)/K315*100)
A322: =M34 | B322: =BDH(A322&" US Equity","IS_DILUTED_EPS",TEXT(EDATE(TODAY(),-24),"MM/DD/YYYY"),TEXT(TODAY(),"MM/DD/YYYY"),"Per","Q","Days","A","Fill","P") | J322: =BDH(A322&" US Equity","SALES_REV_TURN",TEXT(EDATE(TODAY(),-24),"MM/DD/YYYY"),TEXT(TODAY(),"MM/DD/YYYY"),"Per","Q","Days","A","Fill","P") | L322: =IF(C325=0,IF(C329>0,999,0),IF(C325<0,IF(C329>0,999,0),(C329-C325)/ABS(C325)*100)) | N322: =IF(K325<=0,IF(K329>0,999,0),(K329-K325)/K325*100)
A332: =M35 | B332: =BDH(A332&" US Equity","IS_DILUTED_EPS",TEXT(EDATE(TODAY(),-24),"MM/DD/YYYY"),TEXT(TODAY(),"MM/DD/YYYY"),"Per","Q","Days","A","Fill","P") | J332: =BDH(A332&" US Equity","SALES_REV_TURN",TEXT(EDATE(TODAY(),-24),"MM/DD/YYYY"),TEXT(TODAY(),"MM/DD/YYYY"),"Per","Q","Days","A","Fill","P") | L332: =IF(C335=0,IF(C339>0,999,0),IF(C335<0,IF(C339>0,999,0),(C339-C335)/ABS(C335)*100)) | N332: =IF(K335<=0,IF(K339>0,999,0),(K339-K335)/K335*100)
A342: =M36 | B342: =BDH(A342&" US Equity","IS_DILUTED_EPS",TEXT(EDATE(TODAY(),-24),"MM/DD/YYYY"),TEXT(TODAY(),"MM/DD/YYYY"),"Per","Q","Days","A","Fill","P") | J342: =BDH(A342&" US Equity","SALES_REV_TURN",TEXT(EDATE(TODAY(),-24),"MM/DD/YYYY"),TEXT(TODAY(),"MM/DD/YYYY"),"Per","Q","Days","A","Fill","P") | L342: =IF(C345=0,IF(C349>0,999,0),IF(C345<0,IF(C349>0,999,0),(C349-C345)/ABS(C345)*100)) | N342: =IF(K345<=0,IF(K349>0,999,0),(K349-K345)/K345*100)
A352: =M37 | B352: =BDH(A352&" US Equity","IS_DILUTED_EPS",TEXT(EDATE(TODAY(),-24),"MM/DD/YYYY"),TEXT(TODAY(),"MM/DD/YYYY"),"Per","Q","Days","A","Fill","P") | J352: =BDH(A352&" US Equity","SALES_REV_TURN",TEXT(EDATE(TODAY(),-24),"MM/DD/YYYY"),TEXT(TODAY(),"MM/DD/YYYY"),"Per","Q","Days","A","Fill","P") | L352: =IF(C355=0,IF(C359>0,999,0),IF(C355<0,IF(C359>0,999,0),(C359-C355)/ABS(C355)*100)) | N352: =IF(K355<=0,IF(K359>0,999,0),(K359-K355)/K355*100)
A362: =M38 | B362: =BDH(A362&" US Equity","IS_DILUTED_EPS",TEXT(EDATE(TODAY(),-24),"MM/DD/YYYY"),TEXT(TODAY(),"MM/DD/YYYY"),"Per","Q","Days","A","Fill","P") | J362: =BDH(A362&" US Equity","SALES_REV_TURN",TEXT(EDATE(TODAY(),-24),"MM/DD/YYYY"),TEXT(TODAY(),"MM/DD/YYYY"),"Per","Q","Days","A","Fill","P") | L362: =IF(C365=0,IF(C369>0,999,0),IF(C365<0,IF(C369>0,999,0),(C369-C365)/ABS(C365)*100)) | N362: =IF(K365<=0,IF(K369>0,999,0),(K369-K365)/K365*100)
A372: =M39 | B372: =BDH(A372&" US Equity","IS_DILUTED_EPS",TEXT(EDATE(TODAY(),-24),"MM/DD/YYYY"),TEXT(TODAY(),"MM/DD/YYYY"),"Per","Q","Days","A","Fill","P") | J372: =BDH(A372&" US Equity","SALES_REV_TURN",TEXT(EDATE(TODAY(),-24),"MM/DD/YYYY"),TEXT(TODAY(),"MM/DD/YYYY"),"Per","Q","Days","A","Fill","P") | L372: =IF(C375=0,IF(C379>0,999,0),IF(C375<0,IF(C379>0,999,0),(C379-C375)/ABS(C375)*100)) | N372: =IF(K375<=0,IF(K379>0,999,0),(K379-K375)/K375*100)
A382: =M40 | B382: =BDH(A382&" US Equity","IS_DILUTED_EPS",TEXT(EDATE(TODAY(),-24),"MM/DD/YYYY"),TEXT(TODAY(),"MM/DD/YYYY"),"Per","Q","Days","A","Fill","P") | J382: =BDH(A382&" US Equity","SALES_REV_TURN",TEXT(EDATE(TODAY(),-24),"MM/DD/YYYY"),TEXT(TODAY(),"MM/DD/YYYY"),"Per","Q","Days","A","Fill","P") | L382: =IF(C385=0,IF(C389>0,999,0),IF(C385<0,IF(C389>0,999,0),(C389-C385)/ABS(C385)*100)) | N382: =IF(K385<=0,IF(K389>0,999,0),(K389-K385)/K385*100)
...

Sheet Factor Scores
A1: Ticker | B1: 6-Mo Return (%) | C1: RS Percentile | D1: EPS Growth YoY | E1: EPS (capped) | F1: Rev Growth YoY | G1: Rev (capped) | H1: Price vs 52Wk High (%) | I1: Qual: EPS≥5% | J1: Qual: Rev≥5% | K1: Qual: Price≥75% | L1: ALL QUALITY PASS
A2: =Universe!A2 | C2: =IF(B2="","",PERCENTRANK.INC($B$2:$B$2501,B2)*100) | E2: =IF(D2="","",MIN(D2,100)) | G2: =IF(F2="","",MIN(F2,100)) | H2: =IF(A2="","",Universe!E2/BDP(A2&" US Equity","HIGH_52WEEK")*100) | I2: =IF(D2="","",D2>=5) | J2: =IF(F2="","",F2>=5) | K2: =IF(H2="","",H2>=75) | L2: =IF(OR(I2="",J2="",K2=""),FALSE,AND(I2,J2,K2))
A3: =Universe!A3 | C3: =IF(B3="","",PERCENTRANK.INC($B$2:$B$2501,B3)*100) | E3: =IF(D3="","",MIN(D3,100)) | G3: =IF(F3="","",MIN(F3,100)) | H3: =IF(A3="","",Universe!E3/BDP(A3&" US Equity","HIGH_52WEEK")*100) | I3: =IF(D3="","",D3>=5) | J3: =IF(F3="","",F3>=5) | K3: =IF(H3="","",H3>=75) | L3: =IF(OR(I3="",J3="",K3=""),FALSE,AND(I3,J3,K3))
A4: =Universe!A4 | C4: =IF(B4="","",PERCENTRANK.INC($B$2:$B$2501,B4)*100) | E4: =IF(D4="","",MIN(D4,100)) | G4: =IF(F4="","",MIN(F4,100)) | H4: =IF(A4="","",Universe!E4/BDP(A4&" US Equity","HIGH_52WEEK")*100) | I4: =IF(D4="","",D4>=5) | J4: =IF(F4="","",F4>=5) | K4: =IF(H4="","",H4>=75) | L4: =IF(OR(I4="",J4="",K4=""),FALSE,AND(I4,J4,K4))
A5: =Universe!A5 | C5: =IF(B5="","",PERCENTRANK.INC($B$2:$B$2501,B5)*100) | E5: =IF(D5="","",MIN(D5,100)) | G5: =IF(F5="","",MIN(F5,100)) | H5: =IF(A5="","",Universe!E5/BDP(A5&" US Equity","HIGH_52WEEK")*100) | I5: =IF(D5="","",D5>=5) | J5: =IF(F5="","",F5>=5) | K5: =IF(H5="","",H5>=75) | L5: =IF(OR(I5="",J5="",K5=""),FALSE,AND(I5,J5,K5))
A6: =Universe!A6 | C6: =IF(B6="","",PERCENTRANK.INC($B$2:$B$2501,B6)*100) | E6: =IF(D6="","",MIN(D6,100)) | G6: =IF(F6="","",MIN(F6,100)) | H6: =IF(A6="","",Universe!E6/BDP(A6&" US Equity","HIGH_52WEEK")*100) | I6: =IF(D6="","",D6>=5) | J6: =IF(F6="","",F6>=5) | K6: =IF(H6="","",H6>=75) | L6: =IF(OR(I6="",J6="",K6=""),FALSE,AND(I6,J6,K6))
A7: =Universe!A7 | C7: =IF(B7="","",PERCENTRANK.INC($B$2:$B$2501,B7)*100) | E7: =IF(D7="","",MIN(D7,100)) | G7: =IF(F7="","",MIN(F7,100)) | H7: =IF(A7="","",Universe!E7/BDP(A7&" US Equity","HIGH_52WEEK")*100) | I7: =IF(D7="","",D7>=5) | J7: =IF(F7="","",F7>=5) | K7: =IF(H7="","",H7>=75) | L7: =IF(OR(I7="",J7="",K7=""),FALSE,AND(I7,J7,K7))
A8: =Universe!A8 | C8: =IF(B8="","",PERCENTRANK.INC($B$2:$B$2501,B8)*100) | E8: =IF(D8="","",MIN(D8,100)) | G8: =IF(F8="","",MIN(F8,100)) | H8: =IF(A8="","",Universe!E8/BDP(A8&" US Equity","HIGH_52WEEK")*100) | I8: =IF(D8="","",D8>=5) | J8: =IF(F8="","",F8>=5) | K8: =IF(H8="","",H8>=75) | L8: =IF(OR(I8="",J8="",K8=""),FALSE,AND(I8,J8,K8))
A9: =Universe!A9 | C9: =IF(B9="","",PERCENTRANK.INC($B$2:$B$2501,B9)*100) | E9: =IF(D9="","",MIN(D9,100)) | G9: =IF(F9="","",MIN(F9,100)) | H9: =IF(A9="","",Universe!E9/BDP(A9&" US Equity","HIGH_52WEEK")*100) | I9: =IF(D9="","",D9>=5) | J9: =IF(F9="","",F9>=5) | K9: =IF(H9="","",H9>=75) | L9: =IF(OR(I9="",J9="",K9=""),FALSE,AND(I9,J9,K9))
A10: =Universe!A10 | C10: =IF(B10="","",PERCENTRANK.INC($B$2:$B$2501,B10)*100) | E10: =IF(D10="","",MIN(D10,100)) | G10: =IF(F10="","",MIN(F10,100)) | H10: =IF(A10="","",Universe!E10/BDP(A10&" US Equity","HIGH_52WEEK")*100) | I10: =IF(D10="","",D10>=5) | J10: =IF(F10="","",F10>=5) | K10: =IF(H10="","",H10>=75) | L10: =IF(OR(I10="",J10="",K10=""),FALSE,AND(I10,J10,K10))
A11: =Universe!A11 | C11: =IF(B11="","",PERCENTRANK.INC($B$2:$B$2501,B11)*100) | E11: =IF(D11="","",MIN(D11,100)) | G11: =IF(F11="","",MIN(F11,100)) | H11: =IF(A11="","",Universe!E11/BDP(A11&" US Equity","HIGH_52WEEK")*100) | I11: =IF(D11="","",D11>=5) | J11: =IF(F11="","",F11>=5) | K11: =IF(H11="","",H11>=75) | L11: =IF(OR(I11="",J11="",K11=""),FALSE,AND(I11,J11,K11))
A12: =Universe!A12 | C12: =IF(B12="","",PERCENTRANK.INC($B$2:$B$2501,B12)*100) | E12: =IF(D12="","",MIN(D12,100)) | G12: =IF(F12="","",MIN(F12,100)) | H12: =IF(A12="","",Universe!E12/BDP(A12&" US Equity","HIGH_52WEEK")*100) | I12: =IF(D12="","",D12>=5) | J12: =IF(F12="","",F12>=5) | K12: =IF(H12="","",H12>=75) | L12: =IF(OR(I12="",J12="",K12=""),FALSE,AND(I12,J12,K12))
A13: =Universe!A13 | C13: =IF(B13="","",PERCENTRANK.INC($B$2:$B$2501,B13)*100) | E13: =IF(D13="","",MIN(D13,100)) | G13: =IF(F13="","",MIN(F13,100)) | H13: =IF(A13="","",Universe!E13/BDP(A13&" US Equity","HIGH_52WEEK")*100) | I13: =IF(D13="","",D13>=5) | J13: =IF(F13="","",F13>=5) | K13: =IF(H13="","",H13>=75) | L13: =IF(OR(I13="",J13="",K13=""),FALSE,AND(I13,J13,K13))
... A2501: =Universe!A2501 | C2501: =IF(B2501="","",PERCENTRANK.INC($B$2:$B$2501,B2501)*100) | E2501: =IF(D2501="","",MIN(D2501,100)) | G2501: =IF(F2501="","",MIN(F2501,100)) | H2501: =IF(A2501="","",Universe!E2501/BDP(A2501&" US Equity","HIGH_52WEEK")*100) | I2501: =IF(D2501="","",D2501>=5) | J2501: =IF(F2501="","",F2501>=5) | K2501: =IF(H2501="","",H2501>=75) | L2501: =IF(OR(I2501="",J2501="",K2501=""),FALSE,AND(I2501,J2501,K2501))

Sheet Portfolio
A1: Ticker | B1: Composite Score | C1: Rank | D1: Top 25? | E1: Prior Month | F1: Signal | G1: Weight (%) | H1: Sector
A2: ='Factor Scores'!A2 | B2: =IF(A2="","",0.40*'Factor Scores'!C2+0.20*'Factor Scores'!E2+0.20*'Factor Scores'!G2+0.20*'Factor Scores'!H2) | C2: =IF(B2="","",RANK(B2,$B$2:$B$2501,0)) | D2: =IF(C2="","",C2<=25) | F2: =IF(A2="","",IF(AND(D2=TRUE,E2=""),"BUY",IF(AND(D2=FALSE,E2<>""),"SELL",IF(AND(D2=TRUE,E2<>""),"HOLD","")))) | G2: =IF(D2=TRUE,4,0) | H2: =IF(A2="","",BDP(A2&" US Equity","GICS_SECTOR_NAME"))
A3: ='Factor Scores'!A3 | B3: =IF(A3="","",0.40*'Factor Scores'!C3+0.20*'Factor Scores'!E3+0.20*'Factor Scores'!G3+0.20*'Factor Scores'!H3) | C3: =IF(B3="","",RANK(B3,$B$2:$B$2501,0)) | D3: =IF(C3="","",C3<=25) | F3: =IF(A3="","",IF(AND(D3=TRUE,E3=""),"BUY",IF(AND(D3=FALSE,E3<>""),"SELL",IF(AND(D3=TRUE,E3<>""),"HOLD","")))) | G3: =IF(D3=TRUE,4,0) | H3: =IF(A3="","",BDP(A3&" US Equity","GICS_SECTOR_NAME"))
A4: ='Factor Scores'!A4 | B4: =IF(A4="","",0.40*'Factor Scores'!C4+0.20*'Factor Scores'!E4+0.20*'Factor Scores'!G4+0.20*'Factor Scores'!H4) | C4: =IF(B4="","",RANK(B4,$B$2:$B$2501,0)) | D4: =IF(C4="","",C4<=25) | F4: =IF(A4="","",IF(AND(D4=TRUE,E4=""),"BUY",IF(AND(D4=FALSE,E4<>""),"SELL",IF(AND(D4=TRUE,E4<>""),"HOLD","")))) | G4: =IF(D4=TRUE,4,0) | H4: =IF(A4="","",BDP(A4&" US Equity","GICS_SECTOR_NAME"))
A5: ='Factor Scores'!A5 | B5: =IF(A5="","",0.40*'Factor Scores'!C5+0.20*'Factor Scores'!E5+0.20*'Factor Scores'!G5+0.20*'Factor Scores'!H5) | C5: =IF(B5="","",RANK(B5,$B$2:$B$2501,0)) | D5: =IF(C5="","",C5<=25) | F5: =IF(A5="","",IF(AND(D5=TRUE,E5=""),"BUY",IF(AND(D5=FALSE,E5<>""),"SELL",IF(AND(D5=TRUE,E5<>""),"HOLD","")))) | G5: =IF(D5=TRUE,4,0) | H5: =IF(A5="","",BDP(A5&" US Equity","GICS_SECTOR_NAME"))
A6: ='Factor Scores'!A6 | B6: =IF(A6="","",0.40*'Factor Scores'!C6+0.20*'Factor Scores'!E6+0.20*'Factor Scores'!G6+0.20*'Factor Scores'!H6) | C6: =IF(B6="","",RANK(B6,$B$2:$B$2501,0)) | D6: =IF(C6="","",C6<=25) | F6: =IF(A6="","",IF(AND(D6=TRUE,E6=""),"BUY",IF(AND(D6=FALSE,E6<>""),"SELL",IF(AND(D6=TRUE,E6<>""),"HOLD","")))) | G6: =IF(D6=TRUE,4,0) | H6: =IF(A6="","",BDP(A6&" US Equity","GICS_SECTOR_NAME"))
A7: ='Factor Scores'!A7 | B7: =IF(A7="","",0.40*'Factor Scores'!C7+0.20*'Factor Scores'!E7+0.20*'Factor Scores'!G7+0.20*'Factor Scores'!H7) | C7: =IF(B7="","",RANK(B7,$B$2:$B$2501,0)) | D7: =IF(C7="","",C7<=25) | F7: =IF(A7="","",IF(AND(D7=TRUE,E7=""),"BUY",IF(AND(D7=FALSE,E7<>""),"SELL",IF(AND(D7=TRUE,E7<>""),"HOLD","")))) | G7: =IF(D7=TRUE,4,0) | H7: =IF(A7="","",BDP(A7&" US Equity","GICS_SECTOR_NAME"))
A8: ='Factor Scores'!A8 | B8: =IF(A8="","",0.40*'Factor Scores'!C8+0.20*'Factor Scores'!E8+0.20*'Factor Scores'!G8+0.20*'Factor Scores'!H8) | C8: =IF(B8="","",RANK(B8,$B$2:$B$2501,0)) | D8: =IF(C8="","",C8<=25) | F8: =IF(A8="","",IF(AND(D8=TRUE,E8=""),"BUY",IF(AND(D8=FALSE,E8<>""),"SELL",IF(AND(D8=TRUE,E8<>""),"HOLD","")))) | G8: =IF(D8=TRUE,4,0) | H8: =IF(A8="","",BDP(A8&" US Equity","GICS_SECTOR_NAME"))
A9: ='Factor Scores'!A9 | B9: =IF(A9="","",0.40*'Factor Scores'!C9+0.20*'Factor Scores'!E9+0.20*'Factor Scores'!G9+0.20*'Factor Scores'!H9) | C9: =IF(B9="","",RANK(B9,$B$2:$B$2501,0)) | D9: =IF(C9="","",C9<=25) | F9: =IF(A9="","",IF(AND(D9=TRUE,E9=""),"BUY",IF(AND(D9=FALSE,E9<>""),"SELL",IF(AND(D9=TRUE,E9<>""),"HOLD","")))) | G9: =IF(D9=TRUE,4,0) | H9: =IF(A9="","",BDP(A9&" US Equity","GICS_SECTOR_NAME"))
A10: ='Factor Scores'!A10 | B10: =IF(A10="","",0.40*'Factor Scores'!C10+0.20*'Factor Scores'!E10+0.20*'Factor Scores'!G10+0.20*'Factor Scores'!H10) | C10: =IF(B10="","",RANK(B10,$B$2:$B$2501,0)) | D10: =IF(C10="","",C10<=25) | F10: =IF(A10="","",IF(AND(D10=TRUE,E10=""),"BUY",IF(AND(D10=FALSE,E10<>""),"SELL",IF(AND(D10=TRUE,E10<>""),"HOLD","")))) | G10: =IF(D10=TRUE,4,0) | H10: =IF(A10="","",BDP(A10&" US Equity","GICS_SECTOR_NAME"))
A11: ='Factor Scores'!A11 | B11: =IF(A11="","",0.40*'Factor Scores'!C11+0.20*'Factor Scores'!E11+0.20*'Factor Scores'!G11+0.20*'Factor Scores'!H11) | C11: =IF(B11="","",RANK(B11,$B$2:$B$2501,0)) | D11: =IF(C11="","",C11<=25) | F11: =IF(A11="","",IF(AND(D11=TRUE,E11=""),"BUY",IF(AND(D11=FALSE,E11<>""),"SELL",IF(AND(D11=TRUE,E11<>""),"HOLD","")))) | G11: =IF(D11=TRUE,4,0) | H11: =IF(A11="","",BDP(A11&" US Equity","GICS_SECTOR_NAME"))
A12: ='Factor Scores'!A12 | B12: =IF(A12="","",0.40*'Factor Scores'!C12+0.20*'Factor Scores'!E12+0.20*'Factor Scores'!G12+0.20*'Factor Scores'!H12) | C12: =IF(B12="","",RANK(B12,$B$2:$B$2501,0)) | D12: =IF(C12="","",C12<=25) | F12: =IF(A12="","",IF(AND(D12=TRUE,E12=""),"BUY",IF(AND(D12=FALSE,E12<>""),"SELL",IF(AND(D12=TRUE,E12<>""),"HOLD","")))) | G12: =IF(D12=TRUE,4,0) | H12: =IF(A12="","",BDP(A12&" US Equity","GICS_SECTOR_NAME"))
A13: ='Factor Scores'!A13 | B13: =IF(A13="","",0.40*'Factor Scores'!C13+0.20*'Factor Scores'!E13+0.20*'Factor Scores'!G13+0.20*'Factor Scores'!H13) | C13: =IF(B13="","",RANK(B13,$B$2:$B$2501,0)) | D13: =IF(C13="","",C13<=25) | F13: =IF(A13="","",IF(AND(D13=TRUE,E13=""),"BUY",IF(AND(D13=FALSE,E13<>""),"SELL",IF(AND(D13=TRUE,E13<>""),"HOLD","")))) | G13: =IF(D13=TRUE,4,0) | H13: =IF(A13="","",BDP(A13&" US Equity","GICS_SECTOR_NAME"))
... A2501: ='Factor Scores'!A2501 | B2501: =IF(A2501="","",0.40*'Factor Scores'!C2501+0.20*'Factor Scores'!E2501+0.20*'Factor Scores'!G2501+0.20*'Factor Scores'!H2501) | C2501: =IF(B2501="","",RANK(B2501,$B$2:$B$2501,0)) | D2501: =IF(C2501="","",C2501<=25) | F2501: =IF(A2501="","",IF(AND(D2501=TRUE,E2501=""),"BUY",IF(AND(D2501=FALSE,E2501<>""),"SELL",IF(AND(D2501=TRUE,E2501<>""),"HOLD","")))) | G2501: =IF(D2501=TRUE,4,0) | H2501: =IF(A2501="","",BDP(A2501&" US Equity","GICS_SECTOR_NAME"))
